<?xml version="1.0"?>
<robot name="ana_robot">
  <!-- Base Link -->
  <link name="base_link">
    <inertial>
      <origin xyz="0.1165 0.0835 0.0395" rpy="0 0 0"/>
      <mass value="0.5"/>
      <inertia ixx="0.00120417" ixy="0" ixz="0" iyy="0.00230104" iyz="0" izz="0.00350521"/>
    </inertial>
    <collision>
      <origin xyz="0.1165 0.0835 0.0395" rpy="0 0 0"/>
      <geometry>
        <mesh filename="file:///home/aidan/ros_ws/src/ana_1_1/meshes/ana_chassis.stl" scale="0.001 0.001 0.001"/>
      </geometry>
    </collision>
    <visual>
      <origin xyz="0.1165 0.0835 0.0395" rpy="0 0 0"/>
      <geometry>
        <mesh filename="file:///home/aidan/ros_ws/src/ana_1_1/meshes/ana_chassis.stl" scale="0.001 0.001 0.001"/>
      </geometry>
      <material name="blue">
        <color rgba="0.25 0.25 1 1"/>
      </material>
    </visual>
  </link>

  <!-- Wheel Links and Joints -->
  <!-- Back Left Wheel -->
  <joint name="back_left_wheel_joint" type="revolute">
    <parent link="base_link"/>
    <child link="back_left_wheel"/>
    <origin xyz="-0.104 0.0975 0" rpy="-1.5708 0 0"/>
    <axis xyz="0 0 1"/>
    <limit lower="-6.28" upper="6.28" effort="1000" velocity="10"/>
  </joint>
  <link name="back_left_wheel">
    <inertial>
      <origin xyz="0 0 0" rpy="0 0 0"/>
      <mass value="0.1"/>
      <inertia ixx="3.248125e-05" ixy="0" ixz="0" iyy="3.248125e-05" iyz="0" izz="5.28125e-05"/>
    </inertial>
    <collision>
      <origin xyz="0 0 0" rpy="0 0 0"/>
      <geometry>
        <sphere radius="0.0325"/>
      </geometry>
    </collision>
    <visual>
      <origin xyz="0 0 0" rpy="0 0 0"/>
      <geometry>
        <cylinder length="0.027" radius="0.0325"/>
      </geometry>
      <material name="black">
        <color rgba="0 0 0 1"/>
      </material>
    </visual>
  </link>

  <!-- Back Right Wheel -->
  <joint name="back_right_wheel_joint" type="revolute">
    <parent link="base_link"/>
    <child link="back_right_wheel"/>
    <origin xyz="-0.104 -0.1005 0" rpy="1.5708 0 0"/>
    <axis xyz="0 0 -1"/>
    <limit lower="-6.28" upper="6.28" effort="1000" velocity="10"/>
  </joint>
  <link name="back_right_wheel">
    <inertial>
      <origin xyz="0 0 0" rpy="0 0 0"/>
      <mass value="0.1"/>
      <inertia ixx="3.248125e-05" ixy="0" ixz="0" iyy="3.248125e-05" iyz="0" izz="5.28125e-05"/>
    </inertial>
    <collision>
      <origin xyz="0 0 0" rpy="0 0 0"/>
      <geometry>
        <sphere radius="0.0325"/>
      </geometry>
    </collision>
    <visual>
      <origin xyz="0 0 0" rpy="0 0 0"/>
      <geometry>
        <cylinder length="0.027" radius="0.0325"/>
      </geometry>
      <material name="black">
        <color rgba="0 0 0 1"/>
      </material>
    </visual>
  </link>

  <!-- Front Left Wheel -->
  <joint name="front_left_wheel_joint" type="revolute">
    <parent link="base_link"/>
    <child link="front_left_wheel"/>
    <origin xyz="0.104 0.0975 0" rpy="-1.5708 0 0"/>
    <axis xyz="0 0 1"/>
    <limit lower="-6.28" upper="6.28" effort="1000" velocity="10"/>
  </joint>
  <link name="front_left_wheel">
    <inertial>
      <origin xyz="0 0 0" rpy="0 0 0"/>
      <mass value="0.1"/>
      <inertia ixx="3.248125e-05" ixy="0" ixz="0" iyy="3.248125e-05" iyz="0" izz="5.28125e-05"/>
    </inertial>
    <collision>
      <origin xyz="0 0 0" rpy="0 0 0"/>
      <geometry>
        <sphere radius="0.0325"/>
      </geometry>
    </collision>
    <visual>
      <origin xyz="0 0 0" rpy="0 0 0"/>
      <geometry>
        <cylinder length="0.027" radius="0.0325"/>
      </geometry>
      <material name="black">
        <color rgba="0 0 0 1"/>
      </material>
    </visual>
  </link>

  <!-- Front Right Wheel -->
  <joint name="front_right_wheel_joint" type="revolute">
    <parent link="base_link"/>
    <child link="front_right_wheel"/>
    <origin xyz="0.104 -0.1005 0" rpy="1.5708 0 0"/>
    <axis xyz="0 0 -1"/>
    <limit lower="-6.28" upper="6.28" effort="1000" velocity="10"/>
  </joint>
  <link name="front_right_wheel">
    <inertial>
      <origin xyz="0 0 0" rpy="0 0 0"/>
      <mass value="0.1"/>
      <inertia ixx="3.248125e-05" ixy="0" ixz="0" iyy="3.248125e-05" iyz="0" izz="5.28125e-05"/>
    </inertial>
    <collision>
      <origin xyz="0 0 0" rpy="0 0 0"/>
      <geometry>
        <sphere radius="0.0325"/>
      </geometry>
    </collision>
    <visual>
      <origin xyz="0 0 0" rpy="0 0 0"/>
      <geometry>
        <cylinder length="0.027" radius="0.0325"/>
      </geometry>
      <material name="black">
        <color rgba="0 0 0 1"/>
      </material>
    </visual>
  </link>

  <!-- Additional Frames -->
  <link name="chassis_joint">
    <inertial>
      <origin xyz="-0.001 0 0" rpy="0 0 0"/>
      <mass value="0.0"/>
      <inertia ixx="0.0" ixy="0.0" ixz="0.0" iyy="0.0" iyz="0.0" izz="0.0"/>
    </inertial>
    <visual>
      <origin xyz="-0.001 0 0" rpy="0 0 0"/>
      <geometry>
        <box size="0.01 0.01 0.01"/>
      </geometry>
      <material name="transparent">
        <color rgba="0 0 0 0"/>
      </material>
    </visual>
  </link>

  <joint name="chassis_attachment" type="fixed">
    <parent link="base_link"/>
    <child link="chassis_joint"/>
    <origin xyz="-0.001 0 0" rpy="0 0 0"/>
  </joint>

  <link name="chassis">
    <inertial>
      <origin xyz="0 0 0" rpy="0 0 0"/>
      <mass value="0.0"/>
      <inertia ixx="0.0" ixy="0.0" ixz="0.0" iyy="0.0" iyz="0.0" izz="0.0"/>
    </inertial>
    <visual>
      <origin xyz="0 0 0" rpy="0 0 0"/>
      <geometry>
        <box size="0.01 0.01 0.01"/>
      </geometry>
      <material name="transparent">
        <color rgba="0 0 0 0"/>
      </material>
    </visual>
  </link>

  <joint name="chassis_fixed" type="fixed">
    <parent link="chassis_joint"/>
    <child link="chassis"/>
    <origin xyz="0 0 0" rpy="0 0 0"/>
  </joint>
</robot>




