<?xml version="1.0" ?>
<!-- =================================================================================== -->
<!-- |    This document was autogenerated by xacro from robot_core.xacro               | -->
<!-- |    EDITING THIS FILE BY HAND IS NOT RECOMMENDED                                 | -->
<!-- =================================================================================== -->
<robot name="ana_robot">
  <!-- Specify some standard inertial calculations https://en.wikipedia.org/wiki/List_of_moments_of_inertia -->
  <!-- These make use of xacro's mathematical functionality -->
  <material name="white">
    <color rgba="1 1 1 1"/>
  </material>
  <material name="orange">
    <color rgba="1 0.3 0.1 1"/>
  </material>
  <material name="blue">
    <color rgba="0.2 0.2 1 1"/>
  </material>
  <material name="black">
    <color rgba="0 0 0 1"/>
  </material>
  <!-- CHASSIS LINK -->
  <link name="base_link">

    </link>
  <joint name="chassis_joint" type="fixed">
    <parent link="base_link"/>
    <child link="chassis"/>
    <origin xyz="-0.001 0 0"/>
  </joint>
  <link name="chassis">
    <visual>
      <origin xyz="0.1175 0.0835 0.0295"/>
      <!-- chassis location ajusted to be in the middle of the chassis -->
      <geometry>
        <mesh filename="package://ana/meshes/ana_chassis.stl" scale="0.001 0.001 0.001"/>
      </geometry>
      <material name="blue"/>
    </visual>
    <collision>
      <origin xyz="0.1175 0.0835 0.0295"/>
      <!-- chassis location ajusted to be in the middle of the chassis -->
      <geometry>
        <mesh filename="package://ana/meshes/ana_chassis.stl" scale="0.001 0.001 0.001"/>
      </geometry>
    </collision>
    <inertial>
      <origin rpy="0 0 0" xyz="0.1175 0.0835 0.0295"/>
      <mass value="0.5"/>
      <inertia ixx="0.0012041666666666668" ixy="0.0" ixz="0.0" iyy="0.0023010416666666665" iyz="0.0" izz="0.0035052083333333333"/>
    </inertial>
  </link>
  <gazebo reference="chassis">
    <material>Gazebo/Blue</material>
  </gazebo>
  <!-- FRONT LEFT WHEEL LINK -->
  <joint name="front_left_wheel_joint" type="continuous">
    <parent link="base_link"/>
    <child link="front_left_wheel"/>
    <origin rpy="-1.5708 0 0" xyz="0.104 0.0975 0"/>
    <axis xyz="0 0 1"/>
  </joint>
  <link name="front_left_wheel">
    <visual>
      <geometry>
        <cylinder length="0.027" radius="0.0325"/>
      </geometry>
      <material name="black"/>
    </visual>
    <collision>
      <geometry>
        <sphere radius="0.0325"/>
      </geometry>
    </collision>
    <inertial>
      <origin rpy="0 0 0" xyz="0 0 0"/>
      <mass value="0.1"/>
      <inertia ixx="3.248125e-05" ixy="0.0" ixz="0.0" iyy="3.248125e-05" iyz="0.0" izz="5.281250000000001e-05"/>
    </inertial>
  </link>
  <gazebo reference="front_left_wheel">
    <material>Gazebo/Black</material>
  </gazebo>
  <!-- FRONT RIGHT WHEEL LINK -->
  <joint name="front_right_wheel_joint" type="continuous">
    <parent link="base_link"/>
    <child link="front_right_wheel"/>
    <origin rpy="1.5708 0 0" xyz="0.104 -0.1005 0"/>
    <axis xyz="0 0 -1"/>
  </joint>
  <link name="front_right_wheel">
    <visual>
      <geometry>
        <cylinder length="0.027" radius="0.0325"/>
      </geometry>
      <material name="black"/>
    </visual>
    <collision>
      <geometry>
        <sphere radius="0.0325"/>
      </geometry>
    </collision>
    <inertial>
      <origin rpy="0 0 0" xyz="0 0 0"/>
      <mass value="0.1"/>
      <inertia ixx="3.248125e-05" ixy="0.0" ixz="0.0" iyy="3.248125e-05" iyz="0.0" izz="5.281250000000001e-05"/>
    </inertial>
  </link>
  <gazebo reference="front_right_wheel">
    <material>Gazebo/Black</material>
  </gazebo>
  <!-- BACK LEFT WHEEL LINK -->
  <joint name="back_left_wheel_joint" type="continuous">
    <parent link="base_link"/>
    <child link="back_left_wheel"/>
    <origin rpy="-1.5708 0 0" xyz="-0.104 0.0975 0"/>
    <axis xyz="0 0 1"/>
  </joint>
  <link name="back_left_wheel">
    <visual>
      <geometry>
        <cylinder length="0.027" radius="0.0325"/>
      </geometry>
      <material name="black"/>
    </visual>
    <collision>
      <geometry>
        <sphere radius="0.0325"/>
      </geometry>
    </collision>
    <inertial>
      <origin rpy="0 0 0" xyz="0 0 0"/>
      <mass value="0.1"/>
      <inertia ixx="3.248125e-05" ixy="0.0" ixz="0.0" iyy="3.248125e-05" iyz="0.0" izz="5.281250000000001e-05"/>
    </inertial>
  </link>
  <gazebo reference="back_left_wheel">
    <material>Gazebo/Black</material>
    <!-- <mu1 value="0.001"/> -->
    <!--friction does not want to work -->
    <!-- <mu2 value="0.001"/> -->
  </gazebo>
  <!-- BACK RIGHT WHEEL LINK -->
  <joint name="back_right_wheel_joint" type="continuous">
    <parent link="base_link"/>
    <child link="back_right_wheel"/>
    <origin rpy="1.5708 0 0" xyz="-0.104 -0.1005 0"/>
    <axis xyz="0 0 -1"/>
  </joint>
  <link name="back_right_wheel">
    <visual>
      <geometry>
        <cylinder length="0.027" radius="0.0325"/>
      </geometry>
      <material name="black"/>
    </visual>
    <collision>
      <geometry>
        <sphere radius="0.0325"/>
      </geometry>
    </collision>
    <inertial>
      <origin rpy="0 0 0" xyz="0 0 0"/>
      <mass value="0.1"/>
      <inertia ixx="3.248125e-05" ixy="0.0" ixz="0.0" iyy="3.248125e-05" iyz="0.0" izz="5.281250000000001e-05"/>
    </inertial>
  </link>
  <gazebo reference="back_right_wheel">
    <material>Gazebo/Black</material>
    <!-- <mu1 value="0.001"/> -->
    <!--friction does not want to work -->
    <!-- <mu2 value="0.001"/> -->
  </gazebo>
</robot>
