<?xml version="1.0" ?>
<sdf version="1.10">
    <world name="car_world">
        <physics name="1ms" type="ignored">
            <max_step_size>0.001</max_step_size>
            <real_time_factor>1.0</real_time_factor>
        </physics>
        <plugin filename="gz-sim-physics-system" name="gz::sim::systems::Physics"></plugin>
        <plugin filename="gz-sim-user-commands-system" name="gz::sim::systems::UserCommands"></plugin>
        <plugin filename="gz-sim-scene-broadcaster-system" name="gz::sim::systems::SceneBroadcaster"></plugin>
        <!-- <plugin filename="MinimalScene" name="3D View">
            <gz-gui>
                <title>3D View</title>
                <property type="bool" key="showTitleBar">false</property>
                <property type="string" key="state">docked</property>
            </gz-gui>
            <engine>ogre2</engine>
            <scene>scene</scene>
            <ambient_light>0.4 0.4 0.4</ambient_light>
            <background_color>0.8 0.8 0.8</background_color>
            <camera_pose>-6 0 6 0 0.5 0</camera_pose>
            <camera_clip>
                <near>0.25</near>
                <far>25000</far>
            </camera_clip>
        </plugin> -->
        <!-- <plugin filename="GzSceneManager" name="Scene Manager">
            <gz-gui>
                <property key="resizable" type="bool">false</property>
                <property key="width" type="double">5</property>
                <property key="height" type="double">5</property>
                <property key="state" type="string">floating</property>
                <property key="showTitleBar" type="bool">false</property>
            </gz-gui>
        </plugin> -->
        <light type="directional" name="sun">
            <cast_shadows>true</cast_shadows>
            <pose>0 0 10 0 0 0</pose>
            <diffuse>0.8 0.8 0.8 1</diffuse>
            <specular>0.2 0.2 0.2 1</specular>
            <attenuation>
                <range>1000</range>
                <constant>0.9</constant>
                <linear>0.01</linear>
                <quadratic>0.001</quadratic>
            </attenuation>
            <direction>-0.5 0.1 -0.9</direction>
        </light>
        <model name="ground_plane">
            <static>true</static>
            <link name="link">
                <collision name="collision">
                    <geometry>
                        <plane>
                            <normal>0 0 1</normal>
                            <size>100 100</size>
                        </plane>
                    </geometry>
                </collision>
                <visual name="visual">
                    <geometry>
                        <plane>
                            <normal>0 0 1</normal>
                            <size>100 100</size>
                        </plane>
                    </geometry>
                    <material>
                        <ambient>0.8 0.8 0.8 1</ambient>
                        <diffuse>0.8 0.8 0.8 1</diffuse>
                        <specular>0.8 0.8 0.8 1</specular>
                    </material>
                </visual>
            </link>
        </model>

        <model name='ana_robot'>
          <link name='base_link'>
              <inertial>
                  <pose>0.1165 0.0835 0.0295 0 0 0</pose>
                  <mass>0.5</mass>
                  <inertia>
                      <ixx>0.00120417</ixx>
                      <ixy>0</ixy>
                      <ixz>0</ixz>
                      <iyy>0.00230104</iyy>
                      <iyz>0</iyz>
                      <izz>0.00350521</izz>
                  </inertia>
              </inertial>
              <collision name='base_link_fixed_joint_lump__chassis_collision'>
                  <pose>0.1165 0.0835 0.0295 0 0 0</pose>
                  <geometry>
                      <mesh>
                          <scale>0.001 0.001 0.001</scale>
                          <uri>file:///home/aidan/ros_ws/src/ana_1_1/meshes/ana_chassis.stl</uri>
                      </mesh>
                  </geometry>
                  <surface>
                      <contact><ode/></contact>
                      <friction><ode/></friction>
                  </surface>
              </collision>
              <visual name='base_link_fixed_joint_lump__chassis_visual'>
                  <pose>0.1165 0.0835 0.0295 0 0 0</pose>
                  <geometry>
                      <mesh>
                          <scale>0.001 0.001 0.001</scale>
                          <uri>file:///home/aidan/ros_ws/src/ana_1_1/meshes/ana_chassis.stl</uri>
                      </mesh>
                  </geometry>
                  <material>
                      <script>
                          <name>Gazebo/Blue</name>
                          <uri>file://media/materials/scripts/gazebo.material</uri>
                      </script>
                      <diffuse>0.25 0.25 1 1</diffuse>
                      <ambient>0.25 0.25 1 1</ambient>
                  </material>
              </visual>
          </link>
          <joint name='back_left_wheel_joint' type='revolute'>
              <pose relative_to='base_link'>-0.104 0.0975 0 -1.5708 0 0</pose>
              <parent>base_link</parent>
              <child>back_left_wheel</child>
              <axis>
                  <xyz>0 0 1</xyz>
                  <limit>
                      <lower>-inf</lower>
                      <upper>inf</upper>
                  </limit>
                  <dynamics>
                      <spring_reference>0</spring_reference>
                      <spring_stiffness>0</spring_stiffness>
                  </dynamics>
              </axis>
          </joint>
          <link name='back_left_wheel'>
              <pose relative_to='back_left_wheel_joint'>0 0 0 0 0 0</pose>
              <inertial>
                  <pose>0 0 0 0 0 0</pose>
                  <mass>0.1</mass>
                  <inertia>
                      <ixx>3.248125e-05</ixx>
                      <ixy>0</ixy>
                      <ixz>0</ixz>
                      <iyy>3.248125e-05</iyy>
                      <iyz>0</iyz>
                      <izz>5.28125e-05</izz>
                  </inertia>
              </inertial>
              <collision name='back_left_wheel_collision'>
                  <pose>0 0 0 0 0 0</pose>
                  <geometry>
                      <sphere>
                          <radius>0.0325</radius>
                      </sphere>
                  </geometry>
                  <surface>
                      <contact><ode/></contact>
                      <friction><ode/></friction>
                  </surface>
              </collision>
              <visual name='back_left_wheel_visual'>
                  <pose>0 0 0 0 0 0</pose>
                  <geometry>
                      <cylinder>
                          <length>0.027</length>
                          <radius>0.0325</radius>
                      </cylinder>
                  </geometry>
                  <material>
                      <script>
                          <name>Gazebo/Black</name>
                          <uri>file://media/materials/scripts/gazebo.material</uri>
                      </script>
                      <diffuse>0 0 0 1</diffuse>
                      <ambient>0 0 0 1</ambient>
                  </material>
              </visual>
          </link>


          <joint name='back_right_wheel_joint' type='revolute'>
            <pose relative_to='base_link'>-0.104 -0.1005 0 1.5708 0 0</pose>
            <parent>base_link</parent>
            <child>back_right_wheel</child>
            <axis>
                <xyz>0 0 -1</xyz>
                <limit>
                    <lower>-inf</lower>
                    <upper>inf</upper>
                </limit>
                <dynamics>
                    <spring_reference>0</spring_reference>
                    <spring_stiffness>0</spring_stiffness>
                </dynamics>
            </axis>
          </joint>
          <link name='back_right_wheel'>
              <pose relative_to='back_right_wheel_joint'>0 0 0 0 0 0</pose>
              <inertial>
                  <pose>0 0 0 0 0 0</pose>
                  <mass>0.1</mass>
                  <inertia>
                      <ixx>3.248125e-05</ixx>
                      <ixy>0</ixy>
                      <ixz>0</ixz>
                      <iyy>3.248125e-05</iyy>
                      <iyz>0</iyz>
                      <izz>5.28125e-05</izz>
                  </inertia>
              </inertial>
              <collision name='back_right_wheel_collision'>
                  <pose>0 0 0 0 0 0</pose>
                  <geometry>
                      <sphere>
                          <radius>0.0325</radius>
                      </sphere>
                  </geometry>
                  <surface>
                      <contact><ode/></contact>
                      <friction><ode/></friction>
                  </surface>
              </collision>
              <visual name='back_right_wheel_visual'>
                  <pose>0 0 0 0 0 0</pose>
                  <geometry>
                      <cylinder>
                          <length>0.027</length>
                          <radius>0.0325</radius>
                      </cylinder>
                  </geometry>
                  <material>
                      <script>
                          <name>Gazebo/Black</name>
                          <uri>file://media/materials/scripts/gazebo.material</uri>
                      </script>
                      <diffuse>0 0 0 1</diffuse>
                      <ambient>0 0 0 1</ambient>
                  </material>
              </visual>
          </link>
          <joint name='front_left_wheel_joint' type='revolute'>
              <pose relative_to='base_link'>0.104 0.0975 0 -1.5708 0 0</pose>
              <parent>base_link</parent>
              <child>front_left_wheel</child>
              <axis>
                  <xyz>0 0 1</xyz>
                  <limit>
                      <lower>-inf</lower>
                      <upper>inf</upper>
                  </limit>
                  <dynamics>
                      <spring_reference>0</spring_reference>
                      <spring_stiffness>0</spring_stiffness>
                  </dynamics>
              </axis>
          </joint>
          <link name='front_left_wheel'>
              <pose relative_to='front_left_wheel_joint'>0 0 0 0 0 0</pose>
              <inertial>
                  <pose>0 0 0 0 0 0</pose>
                  <mass>0.1</mass>
                  <inertia>
                      <ixx>3.248125e-05</ixx>
                      <ixy>0</ixy>
                      <ixz>0</ixz>
                      <iyy>3.248125e-05</iyy>
                      <iyz>0</iyz>
                      <izz>5.28125e-05</izz>
                  </inertia>
              </inertial>
              <collision name='front_left_wheel_collision'>
                  <pose>0 0 0 0 0 0</pose>
                  <geometry>
                      <sphere>
                          <radius>0.0325</radius>
                      </sphere>
                  </geometry>
                  <surface>
                      <contact><ode/></contact>
                      <friction><ode/></friction>
                  </surface>
              </collision>
              <visual name='front_left_wheel_visual'>
                  <pose>0 0 0 0 0 0</pose>
                  <geometry>
                      <cylinder>
                          <length>0.027</length>
                          <radius>0.0325</radius>
                      </cylinder>
                  </geometry>
                  <material>
                      <script>
                          <name>Gazebo/Black</name>
                          <uri>file://media/materials/scripts/gazebo.material</uri>
                      </script>
                      <diffuse>0 0 0 1</diffuse>
                      <ambient>0 0 0 1</ambient>
                  </material>
              </visual>
          </link>
          <joint name='front_right_wheel_joint' type='revolute'>
              <pose relative_to='base_link'>0.104 -0.1005 0 1.5708 0 0</pose>
              <parent>base_link</parent>
              <child>front_right_wheel</child>
              <axis>
                  <xyz>0 0 -1</xyz>
                  <limit>
                      <lower>-inf</lower>
                      <upper>inf</upper>
                  </limit>
                  <dynamics>
                      <spring_reference>0</spring_reference>
                      <spring_stiffness>0</spring_stiffness>
                  </dynamics>
              </axis>
          </joint>
          <link name='front_right_wheel'>
              <pose relative_to='front_right_wheel_joint'>0 0 0 0 0 0</pose>
              <inertial>
                  <pose>0 0 0 0 0 0</pose>
                  <mass>0.1</mass>
                  <inertia>
                      <ixx>3.248125e-05</ixx>
                      <ixy>0</ixy>
                      <ixz>0</ixz>
                      <iyy>3.248125e-05</iyy>
                      <iyz>0</iyz>
                      <izz>5.28125e-05</izz>
                  </inertia>
              </inertial>
              <collision name='front_right_wheel_collision'>
                  <pose>0 0 0 0 0 0</pose>
                  <geometry>
                      <sphere>
                          <radius>0.0325</radius>
                      </sphere>
                  </geometry>
                  <surface>
                      <contact><ode/></contact>
                      <friction><ode/></friction>
                  </surface>
              </collision>
              <visual name='front_right_wheel_visual'>
                  <pose>0 0 0 0 0 0</pose>
                  <geometry>
                      <cylinder>
                          <length>0.027</length>
                          <radius>0.0325</radius>
                      </cylinder>
                  </geometry>
                  <material>
                      <script>
                          <name>Gazebo/Black</name>
                          <uri>file://media/materials/scripts/gazebo.material</uri>
                      </script>
                      <diffuse>0 0 0 1</diffuse>
                      <ambient>0 0 0 1</ambient>
                  </material>
              </visual>
          </link>
          <frame name='chassis_joint' attached_to='base_link'>
              <pose>-0.001 0 0 0 0 0</pose>
          </frame>
          <frame name='chassis' attached_to='chassis_joint'>
              <pose>0 0 0 0 0 0</pose>
          </frame>


          <plugin filename="gz-sim-diff-drive-system" name="gz::sim::systems::DiffDrive">
              <left_joint>front_left_wheel_joint</left_joint>
              <left_joint>back_left_wheel_joint</left_joint>
              <right_joint>front_right_wheel_joint</right_joint>
              <right_joint>back_right_wheel_joint</right_joint>
              <wheel_separation>0.376</wheel_separation> <!-- Based on robot's width -->
              <wheel_radius>0.065</wheel_radius> <!-- Based on actual wheel radius -->
              <odom_publish_frequency>50</odom_publish_frequency>
              <topic>/model/ana_robot/cmd_vel</topic>
              <odom_topic>/model/ana_robot/odometry</odom_topic>
              <tf_topic>/model/ana_robot/tf</tf_topic>
              <frame_id>ana_robot/odom</frame_id>
              <child_frame_id>ana_robot/base_link</child_frame_id>
              <min_velocity>-0.5</min_velocity>
              <max_velocity>0.5</max_velocity>
              <min_acceleration>-0.5</min_acceleration>
              <max_acceleration>0.5</max_acceleration>
              <min_jerk>-0.2</min_jerk>
              <max_jerk>0.2</max_jerk>
              <min_linear_velocity>-0.5</min_linear_velocity>
              <max_linear_velocity>0.5</max_linear_velocity>
              <min_angular_velocity>-1.0</min_angular_velocity>
              <max_angular_velocity>1.0</max_angular_velocity>
              <min_linear_acceleration>-0.5</min_linear_acceleration>
              <max_linear_acceleration>0.5</max_linear_acceleration>
              <min_angular_acceleration>-1.0</min_angular_acceleration>
              <max_angular_acceleration>1.0</max_angular_acceleration>
              <min_linear_jerk>-0.2</min_linear_jerk>
              <max_linear_jerk>0.2</max_linear_jerk>
              <min_angular_jerk>-0.5</min_angular_jerk>
              <max_angular_jerk>0.5</max_angular_jerk>
          </plugin>

          <!-- Moving Forward -->
          <plugin filename="gz-sim-triggered-publisher-system" name="gz::sim::systems::TriggeredPublisher">
              <input type="gz.msgs.Int32" topic="/keyboard/keypress">
                  <match field="data">16777235</match> <!-- Up arrow key for forward -->
              </input>
              <output type="gz.msgs.Twist" topic="/model/ana_robot/cmd_vel">
                  linear: {x: 0.5}, angular: {z: 0.0}
              </output>
          </plugin>

          <!-- Moving Backward -->
          <plugin filename="gz-sim-triggered-publisher-system" name="gz::sim::systems::TriggeredPublisher">
              <input type="gz.msgs.Int32" topic="/keyboard/keypress">
                  <match field="data">16777237</match> <!-- Down arrow key for backward -->
              </input>
              <output type="gz.msgs.Twist" topic="/model/ana_robot/cmd_vel">
                  linear: {x: -0.5}, angular: {z: 0.0}
              </output>
          </plugin>

          <!-- Turning Left -->
          <plugin filename="gz-sim-triggered-publisher-system" name="gz::sim::systems::TriggeredPublisher">
              <input type="gz.msgs.Int32" topic="/keyboard/keypress">
                  <match field="data">16777234</match> <!-- Left arrow key -->
              </input>
              <output type="gz.msgs.Twist" topic="/model/ana_robot/cmd_vel">
                  linear: {x: 0.0}, angular: {z: 1.0} <!-- Positive angular velocity for left turn -->
              </output>
          </plugin>

          <!-- Turning Right -->
          <plugin filename="gz-sim-triggered-publisher-system" name="gz::sim::systems::TriggeredPublisher">
              <input type="gz.msgs.Int32" topic="/keyboard/keypress">
                  <match field="data">16777236</match> <!-- Right arrow key -->
              </input>
              <output type="gz.msgs.Twist" topic="/model/ana_robot/cmd_vel">
                  linear: {x: 0.0}, angular: {z: -1.0} <!-- Negative angular velocity for right turn -->
              </output>
          </plugin>


        </model>
    </world>
</sdf>



