<sdf version='1.11'>
  <model name='ana_robot'>
    <link name='base_link'>
      <inertial>
        <pose>0.11650000000000001 0.083500000000000005 0.029499999999999998 0 0 0</pose>
        <mass>0.5</mass>
        <inertia>
          <ixx>0.001204166666666667</ixx>
          <ixy>0</ixy>
          <ixz>0</ixz>
          <iyy>0.0023010416666666661</iyy>
          <iyz>0</iyz>
          <izz>0.003505208333333332</izz>
        </inertia>
      </inertial>
      <collision name='base_link_fixed_joint_lump__chassis_collision'>
        <pose>0.11650000000000001 0.083500000000000005 0.029499999999999998 0 0 0</pose>
        <geometry>
          <mesh>
            <scale>0.001 0.001 0.001</scale>
            <uri>model://ana/meshes/ana_chassis.stl</uri>
          </mesh>
        </geometry>
        <surface>
          <contact>
            <ode/>
          </contact>
          <friction>
            <ode/>
          </friction>
        </surface>
      </collision>
      <visual name='base_link_fixed_joint_lump__chassis_visual'>
        <pose>0.11650000000000001 0.083500000000000005 0.029499999999999998 0 0 0</pose>
        <geometry>
          <mesh>
            <scale>0.001 0.001 0.001</scale>
            <uri>model://ana/meshes/ana_chassis.stl</uri>
          </mesh>
        </geometry>
        <material>
          <script>
            <name>Gazebo/Blue</name>
            <uri>file://media/materials/scripts/gazebo.material</uri>
          </script>
          <diffuse>0.25 0.25 1 1</diffuse>
          <ambient>0.25 0.25 1 1</ambient>
        </material>
      </visual>
    </link>
    <joint name='back_left_wheel_joint' type='revolute'>
      <pose relative_to='base_link'>-0.104 0.097500000000000003 0 -1.5708 0 0</pose>
      <parent>base_link</parent>
      <child>back_left_wheel</child>
      <axis>
        <xyz>0 0 1</xyz>
        <limit>
          <lower>-inf</lower>
          <upper>inf</upper>
        </limit>
        <dynamics>
          <spring_reference>0</spring_reference>
          <spring_stiffness>0</spring_stiffness>
        </dynamics>
      </axis>
    </joint>
    <link name='back_left_wheel'>
      <pose relative_to='back_left_wheel_joint'>0 0 0 0 0 0</pose>
      <inertial>
        <pose>0 0 0 0 0 0</pose>
        <mass>0.10000000000000001</mass>
        <inertia>
          <ixx>3.248125e-05</ixx>
          <ixy>0</ixy>
          <ixz>0</ixz>
          <iyy>3.248125e-05</iyy>
          <iyz>0</iyz>
          <izz>5.281250000000001e-05</izz>
        </inertia>
      </inertial>
      <collision name='back_left_wheel_collision'>
        <pose>0 0 0 0 0 0</pose>
        <geometry>
          <sphere>
            <radius>0.032500000000000001</radius>
          </sphere>
        </geometry>
        <surface>
          <contact>
            <ode/>
          </contact>
          <friction>
            <ode/>
          </friction>
        </surface>
      </collision>
      <visual name='back_left_wheel_visual'>
        <pose>0 0 0 0 0 0</pose>
        <geometry>
          <cylinder>
            <length>0.027</length>
            <radius>0.032500000000000001</radius>
          </cylinder>
        </geometry>
        <material>
          <script>
            <name>Gazebo/Black</name>
            <uri>file://media/materials/scripts/gazebo.material</uri>
          </script>
          <diffuse>0 0 0 1</diffuse>
          <ambient>0 0 0 1</ambient>
        </material>
      </visual>
    </link>
    <joint name='back_right_wheel_joint' type='revolute'>
      <pose relative_to='base_link'>-0.104 -0.10050000000000001 0 1.5708 0 0</pose>
      <parent>base_link</parent>
      <child>back_right_wheel</child>
      <axis>
        <xyz>0 0 -1</xyz>
        <limit>
          <lower>-inf</lower>
          <upper>inf</upper>
        </limit>
        <dynamics>
          <spring_reference>0</spring_reference>
          <spring_stiffness>0</spring_stiffness>
        </dynamics>
      </axis>
    </joint>
    <link name='back_right_wheel'>
      <pose relative_to='back_right_wheel_joint'>0 0 0 0 0 0</pose>
      <inertial>
        <pose>0 0 0 0 0 0</pose>
        <mass>0.10000000000000001</mass>
        <inertia>
          <ixx>3.248125e-05</ixx>
          <ixy>0</ixy>
          <ixz>0</ixz>
          <iyy>3.248125e-05</iyy>
          <iyz>0</iyz>
          <izz>5.281250000000001e-05</izz>
        </inertia>
      </inertial>
      <collision name='back_right_wheel_collision'>
        <pose>0 0 0 0 0 0</pose>
        <geometry>
          <sphere>
            <radius>0.032500000000000001</radius>
          </sphere>
        </geometry>
        <surface>
          <contact>
            <ode/>
          </contact>
          <friction>
            <ode/>
          </friction>
        </surface>
      </collision>
      <visual name='back_right_wheel_visual'>
        <pose>0 0 0 0 0 0</pose>
        <geometry>
          <cylinder>
            <length>0.027</length>
            <radius>0.032500000000000001</radius>
          </cylinder>
        </geometry>
        <material>
          <script>
            <name>Gazebo/Black</name>
            <uri>file://media/materials/scripts/gazebo.material</uri>
          </script>
          <diffuse>0 0 0 1</diffuse>
          <ambient>0 0 0 1</ambient>
        </material>
      </visual>
    </link>
    <joint name='front_left_wheel_joint' type='revolute'>
      <pose relative_to='base_link'>0.104 0.097500000000000003 0 -1.5708 0 0</pose>
      <parent>base_link</parent>
      <child>front_left_wheel</child>
      <axis>
        <xyz>0 0 1</xyz>
        <limit>
          <lower>-inf</lower>
          <upper>inf</upper>
        </limit>
        <dynamics>
          <spring_reference>0</spring_reference>
          <spring_stiffness>0</spring_stiffness>
        </dynamics>
      </axis>
    </joint>
    <link name='front_left_wheel'>
      <pose relative_to='front_left_wheel_joint'>0 0 0 0 0 0</pose>
      <inertial>
        <pose>0 0 0 0 0 0</pose>
        <mass>0.10000000000000001</mass>
        <inertia>
          <ixx>3.248125e-05</ixx>
          <ixy>0</ixy>
          <ixz>0</ixz>
          <iyy>3.248125e-05</iyy>
          <iyz>0</iyz>
          <izz>5.281250000000001e-05</izz>
        </inertia>
      </inertial>
      <collision name='front_left_wheel_collision'>
        <pose>0 0 0 0 0 0</pose>
        <geometry>
          <sphere>
            <radius>0.032500000000000001</radius>
          </sphere>
        </geometry>
        <surface>
          <contact>
            <ode/>
          </contact>
          <friction>
            <ode/>
          </friction>
        </surface>
      </collision>
      <visual name='front_left_wheel_visual'>
        <pose>0 0 0 0 0 0</pose>
        <geometry>
          <cylinder>
            <length>0.027</length>
            <radius>0.032500000000000001</radius>
          </cylinder>
        </geometry>
        <material>
          <script>
            <name>Gazebo/Black</name>
            <uri>file://media/materials/scripts/gazebo.material</uri>
          </script>
          <diffuse>0 0 0 1</diffuse>
          <ambient>0 0 0 1</ambient>
        </material>
      </visual>
    </link>
    <joint name='front_right_wheel_joint' type='revolute'>
      <pose relative_to='base_link'>0.104 -0.10050000000000001 0 1.5708 0 0</pose>
      <parent>base_link</parent>
      <child>front_right_wheel</child>
      <axis>
        <xyz>0 0 -1</xyz>
        <limit>
          <lower>-inf</lower>
          <upper>inf</upper>
        </limit>
        <dynamics>
          <spring_reference>0</spring_reference>
          <spring_stiffness>0</spring_stiffness>
        </dynamics>
      </axis>
    </joint>
    <link name='front_right_wheel'>
      <pose relative_to='front_right_wheel_joint'>0 0 0 0 0 0</pose>
      <inertial>
        <pose>0 0 0 0 0 0</pose>
        <mass>0.10000000000000001</mass>
        <inertia>
          <ixx>3.248125e-05</ixx>
          <ixy>0</ixy>
          <ixz>0</ixz>
          <iyy>3.248125e-05</iyy>
          <iyz>0</iyz>
          <izz>5.281250000000001e-05</izz>
        </inertia>
      </inertial>
      <collision name='front_right_wheel_collision'>
        <pose>0 0 0 0 0 0</pose>
        <geometry>
          <sphere>
            <radius>0.032500000000000001</radius>
          </sphere>
        </geometry>
        <surface>
          <contact>
            <ode/>
          </contact>
          <friction>
            <ode/>
          </friction>
        </surface>
      </collision>
      <visual name='front_right_wheel_visual'>
        <pose>0 0 0 0 0 0</pose>
        <geometry>
          <cylinder>
            <length>0.027</length>
            <radius>0.032500000000000001</radius>
          </cylinder>
        </geometry>
        <material>
          <script>
            <name>Gazebo/Black</name>
            <uri>file://media/materials/scripts/gazebo.material</uri>
          </script>
          <diffuse>0 0 0 1</diffuse>
          <ambient>0 0 0 1</ambient>
        </material>
      </visual>
    </link>
    <frame name='chassis_joint' attached_to='base_link'>
      <pose>-0.001 0 0 0 0 0</pose>
    </frame>
    <frame name='chassis' attached_to='chassis_joint'>
      <pose>0 0 0 0 0 0</pose>
    </frame>
  </model>
</sdf>
